{
    "registryname" : "carbon_monoxide_generator",
    "localizedname" : "一氧化碳发生器",
    "parts": [
        {
            "x" : 1,
            "y" : 0,
            "z" : 1,
            "elements": [
                "minecraft:water"
            ] 
        },
        {
            "x" : -1,
            "y" : 0,
            "z" : 1,
            "elements": [
                "minecraft:water"
            ]
        },
        {
            "x" : 0,
            "y" : 0,
            "z" : 1,
            "elements": [
                "minecraft:water"
            ]
        },
        {
            "x" : 1,
            "y" : 0,
            "z" : 2,
            "elements": [
                "minecraft:water"
            ]
        },
        {
            "x" : -1,
            "y" : 0,
            "z" : 2,
            "elements": [
                "minecraft:water"
            ] 
        },
        {
            "x" : 0,
            "y" : 0,
            "z" : 2,
            "elements": [
                "minecraft:water"
            ]
        },
        {
            "x" : 1,
            "y" : 0,
            "z" : 3,
            "elements": [
                "minecraft:water"
            ] 
        },
        {
            "x" : -1,
            "y" : 0,
            "z" : 3,
            "elements": [
                "minecraft:water"
            ]
        },
        {
            "x" : 0,
            "y" : 0,
            "z" : 3,
            "elements": [
                "minecraft:water"
            ]
        },
        {
            "x" : 1,
            "y" : -1,
            "z" : 1,
            "elements": [
                "minecraft:water"
            ] 
        },
        {
            "x" : -1,
            "y" : -1,
            "z" : 1,
            "elements": [
                "minecraft:water"
            ]
        },
        {
            "x" : 0,
            "y" : -1,
            "z" : 1,
            "elements": [
                "minecraft:water"
            ]
        },
        {
            "x" : 1,
            "y" : -1,
            "z" : 2,
            "elements": [
                "minecraft:water"
            ]
        },
        {
            "x" : -1,
            "y" : -1,
            "z" : 2,
            "elements": [
                "minecraft:water"
            ] 
        },
        {
            "x" : 0,
            "y" : -1,
            "z" : 2,
            "elements": [
                "minecraft:water"
            ]
        },
        {
            "x" : 1,
            "y" : -1,
            "z" : 3,
            "elements": [
                "minecraft:water"
            ] 
        },
        {
            "x" : -1,
            "y" : -1,
            "z" : 3,
            "elements": [
                "minecraft:water"
            ]
        },
        {
            "x" : 0,
            "y" : -1,
            "z" : 3,
            "elements": [
                "minecraft:water"
            ]
        },
        {
            "x": -1,
            "y": 0,
            "z": 0,
            "elements": [
                "minecraft:glass@0"
            ]
        },
        {
            "x": -2,
            "y": 0,
            "z": 2,
            "elements": [
                "modularmachinery:blockfluidoutputhatch@1"
            ]
        },
        {
            "x": 1,
            "y": 0,
            "z": 0,
            "elements": [
                "minecraft:glass@0"
            ]
        },
        {
            "x": -2,
            "y": 0,
            "z": 3,
            "elements": [
                "minecraft:glass@0"
            ]
        },
        {
            "x": -1,
            "y": -2,
            "z": 1,
            "elements": [
                "modularmachinery:blockcasing@2"
            ]
        },
        {
            "x": -1,
            "y": -2,
            "z": 2,
            "elements": [
                "modularmachinery:blockcasing@2"
            ]
        },
        {
            "x": 2,
            "y": 0,
            "z": 1,
            "elements": [
                "minecraft:glass@0"
            ]
        },
        {
            "x": -1,
            "y": 0,
            "z": 4,
            "elements": [
                "minecraft:glass@0"
            ]
        },
        {
            "x": 0,
            "y": -2,
            "z": 1,
            "elements": [
                "modularmachinery:blockcasing@2"
            ]
        },
        {
            "x": 2,
            "y": 0,
            "z": 2,
            "elements": [
                "modularmachinery:blockfluidoutputhatch@1"
            ]
        },
        {
            "x": -1,
            "y": -2,
            "z": 3,
            "elements": [
                "modularmachinery:blockcasing@2"
            ]
        },
        {
            "x": 1,
            "y": -2,
            "z": 1,
            "elements": [
                "modularmachinery:blockcasing@2"
            ]
        },
        {
            "x": 0,
            "y": 0,
            "z": 4,
            "elements": [
                "minecraft:glass@0"
            ]
        },
        {
            "x": 0,
            "y": -2,
            "z": 2,
            "elements": [
                "modularmachinery:blockcasing@2"
            ]
        },
        {
            "x": 0,
            "y": -2,
            "z": 3,
            "elements": [
                "modularmachinery:blockcasing@2"
            ]
        },
        {
            "x": 1,
            "y": -2,
            "z": 2,
            "elements": [
                "modularmachinery:blockcasing@2"
            ]
        },
        {
            "x": 1,
            "y": 0,
            "z": 4,
            "elements": [
                "minecraft:glass@0"
            ]
        },
        {
            "x": 2,
            "y": 0,
            "z": 3,
            "elements": [
                "minecraft:glass@0"
            ]
        },
        {
            "x": 1,
            "y": -2,
            "z": 3,
            "elements": [
                "modularmachinery:blockcasing@2"
            ]
        },
        {
            "x": 1,
            "y": -1,
            "z": 0,
            "elements": [
                "modularmachinery:blockfluidinputhatch@1"
            ]
        },
        {
            "x": 0,
            "y": -1,
            "z": 0,
            "elements": [
                "modularmachinery:blockinputbus@0"
            ]
        },
        {
            "x": -1,
            "y": -1,
            "z": 0,
            "elements": [
                "modularmachinery:blockfluidinputhatch@1"
            ]
        },
        {
            "x": -1,
            "y": 1,
            "z": 1,
            "elements": [
                "minecraft:glass@0"
            ]
        },
        {
            "x": 0,
            "y": 1,
            "z": 1,
            "elements": [
                "minecraft:glass@0"
            ]
        },
        {
            "x": -2,
            "y": -1,
            "z": 1,
            "elements": [
                "modularmachinery:blockcasing@0"
            ]
        },
        {
            "x": -1,
            "y": 1,
            "z": 2,
            "elements": [
                "minecraft:glass@0"
            ]
        },
        {
            "x": 1,
            "y": 1,
            "z": 1,
            "elements": [
                "minecraft:glass@0"
            ]
        },
        {
            "x": -2,
            "y": -1,
            "z": 2,
            "elements": [
                "modularmachinery:blockcasing@0"
            ]
        },
        {
            "x": -1,
            "y": 1,
            "z": 3,
            "elements": [
                "minecraft:glass@0"
            ]
        },
        {
            "x": 0,
            "y": 1,
            "z": 3,
            "elements": [
                "minecraft:glass@0"
            ]
        },
        {
            "x": 1,
            "y": 1,
            "z": 2,
            "elements": [
                "minecraft:glass@0"
            ]
        },
        {
            "x": -2,
            "y": -1,
            "z": 3,
            "elements": [
                "modularmachinery:blockcasing@0"
            ]
        },
        {
            "x": 1,
            "y": 1,
            "z": 3,
            "elements": [
                "minecraft:glass@0"
            ]
        },
        {
            "x": 2,
            "y": -1,
            "z": 1,
            "elements": [
                "modularmachinery:blockcasing@0"
            ]
        },
        {
            "x": -1,
            "y": -1,
            "z": 4,
            "elements": [
                "modularmachinery:blockcasing@0"
            ]
        },
        {
            "x": 2,
            "y": -1,
            "z": 2,
            "elements": [
                "modularmachinery:blockcasing@0"
            ]
        },
        {
            "x": 0,
            "y": -1,
            "z": 4,
            "elements": [
                "modularmachinery:blockcasing@0"
            ]
        },
        {
            "x": 1,
            "y": -1,
            "z": 4,
            "elements": [
                "modularmachinery:blockcasing@0"
            ]
        },
        {
            "x": 2,
            "y": -1,
            "z": 3,
            "elements": [
                "modularmachinery:blockcasing@0"
            ]
        },
        {
            "x": -2,
            "y": 0,
            "z": 1,
            "elements": [
                "minecraft:glass@0"
            ]
        }
    ]
}