{
    "registryname" : "quenching_tank",
    "localizedname" : "淬火槽",
    "parts": [
        {
            "x": 0,
            "y": -1,
            "z": 1,
            "elements": [
                "minecraft:water"
            ]
        },
        {
            "x": 1,
            "y": -1,
            "z": 1,
            "elements": [
                "minecraft:water"
            ]
        },
        {
            "x": -1,
            "y": -1,
            "z": 1,
            "elements": [
                "minecraft:water"
            ]
        },
        {
            "x": 0,
            "y": -1,
            "z": 2,
            "elements": [
                "minecraft:water"
            ]
        },
        {
            "x": 1,
            "y": -1,
            "z": 2,
            "elements": [
                "minecraft:water"
            ]
        },
        {
            "x": -1,
            "y": -1,
            "z": 2,
            "elements": [
                "minecraft:water"
            ]
        },
        {
            "x": -1,
            "y": 0,
            "z": 0,
            "elements": [
                "modularmachinery:blockinputbus@1"
            ]
        },
        {
            "x": -2,
            "y": 0,
            "z": 2,
            "elements": [
                "minecraft:brick_block@0"
            ]
        },
        {
            "x": -2,
            "y": -2,
            "z": 1,
            "elements": [
                "minecraft:stone_slab@12"
            ]
        },
        {
            "x": 1,
            "y": 0,
            "z": 0,
            "elements": [
                "minecraft:brick_block@0"
            ]
        },
        {
            "x": -2,
            "y": -2,
            "z": 2,
            "elements": [
                "minecraft:stone_slab@12"
            ]
        },
        {
            "x": -1,
            "y": 0,
            "z": 3,
            "elements": [
                "minecraft:brick_block@0"
            ]
        },
        {
            "x": -1,
            "y": -2,
            "z": 1,
            "elements": [
                "minecraft:brick_block@0"
            ]
        },
        {
            "x": -1,
            "y": -2,
            "z": 2,
            "elements": [
                "minecraft:brick_block@0"
            ]
        },
        {
            "x": 2,
            "y": 0,
            "z": 1,
            "elements": [
                "minecraft:brick_block@0"
            ]
        },
        {
            "x": 0,
            "y": 0,
            "z": 3,
            "elements": [
                "minecraft:brick_block@0"
            ]
        },
        {
            "x": 0,
            "y": -2,
            "z": 1,
            "elements": [
                "minecraft:brick_block@0"
            ]
        },
        {
            "x": 2,
            "y": 0,
            "z": 2,
            "elements": [
                "minecraft:brick_block@0"
            ]
        },
        {
            "x": -1,
            "y": -2,
            "z": 3,
            "elements": [
                "minecraft:stone_slab@12"
            ]
        },
        {
            "x": 1,
            "y": -2,
            "z": 1,
            "elements": [
                "minecraft:brick_block@0"
            ]
        },
        {
            "x": 1,
            "y": 0,
            "z": 3,
            "elements": [
                "minecraft:brick_block@0"
            ]
        },
        {
            "x": 0,
            "y": -2,
            "z": 2,
            "elements": [
                "minecraft:brick_block@0"
            ]
        },
        {
            "x": 0,
            "y": -2,
            "z": 3,
            "elements": [
                "minecraft:stone_slab@12"
            ]
        },
        {
            "x": 1,
            "y": -2,
            "z": 2,
            "elements": [
                "minecraft:brick_block@0"
            ]
        },
        {
            "x": 2,
            "y": -2,
            "z": 1,
            "elements": [
                "minecraft:stone_slab@12"
            ]
        },
        {
            "x": 1,
            "y": -2,
            "z": 3,
            "elements": [
                "minecraft:stone_slab@12"
            ]
        },
        {
            "x": 2,
            "y": -2,
            "z": 2,
            "elements": [
                "minecraft:stone_slab@12"
            ]
        },
        {
            "x": 1,
            "y": -1,
            "z": 0,
            "elements": [
                "modularmachinery:blockfluidinputhatch@1"
            ]
        },
        {
            "x": 0,
            "y": -1,
            "z": 0,
            "elements": [
                "minecraft:brick_block@0"
            ]
        },
        {
            "x": -1,
            "y": 1,
            "z": 0,
            "elements": [
                "minecraft:stone_slab@4"
            ]
        },
        {
            "x": -1,
            "y": -1,
            "z": 0,
            "elements": [
                "minecraft:brick_block@0"
            ]
        },
        {
            "x": 0,
            "y": 1,
            "z": 0,
            "elements": [
                "minecraft:stone_slab@4"
            ]
        },
        {
            "x": -1,
            "y": 1,
            "z": 1,
            "elements": [
                "minecraft:stone_slab@4"
            ]
        },
        {
            "x": 0,
            "y": 1,
            "z": 1,
            "elements": [
                "minecraft:glass@0"
            ]
        },
        {
            "x": 1,
            "y": 1,
            "z": 0,
            "elements": [
                "minecraft:stone_slab@4"
            ]
        },
        {
            "x": -2,
            "y": -1,
            "z": 1,
            "elements": [
                "minecraft:brick_block@0"
            ]
        },
        {
            "x": -1,
            "y": 1,
            "z": 2,
            "elements": [
                "minecraft:stone_slab@4"
            ]
        },
        {
            "x": 0,
            "y": 1,
            "z": 2,
            "elements": [
                "minecraft:glass@0"
            ]
        },
        {
            "x": 1,
            "y": 1,
            "z": 1,
            "elements": [
                "minecraft:stone_slab@4"
            ]
        },
        {
            "x": -2,
            "y": -1,
            "z": 2,
            "elements": [
                "minecraft:brick_block@0"
            ]
        },
        {
            "x": -1,
            "y": 1,
            "z": 3,
            "elements": [
                "minecraft:stone_slab@4"
            ]
        },
        {
            "x": 0,
            "y": 1,
            "z": 3,
            "elements": [
                "minecraft:stone_slab@4"
            ]
        },
        {
            "x": 1,
            "y": 1,
            "z": 2,
            "elements": [
                "minecraft:stone_slab@4"
            ]
        },
        {
            "x": 1,
            "y": 1,
            "z": 3,
            "elements": [
                "minecraft:stone_slab@4"
            ]
        },
        {
            "x": -1,
            "y": -1,
            "z": 3,
            "elements": [
                "minecraft:brick_block@0"
            ]
        },
        {
            "x": 0,
            "y": -1,
            "z": 3,
            "elements": [
                "minecraft:brick_block@0"
            ]
        },
        {
            "x": 2,
            "y": -1,
            "z": 1,
            "elements": [
                "minecraft:brick_block@0"
            ]
        },
        {
            "x": 1,
            "y": -1,
            "z": 3,
            "elements": [
                "minecraft:brick_block@0"
            ]
        },
        {
            "x": 2,
            "y": -1,
            "z": 2,
            "elements": [
                "minecraft:brick_block@0"
            ]
        },
        {
            "x": 1,
            "y": -2,
            "z": 0,
            "elements": [
                "minecraft:stone_slab@12"
            ]
        },
        {
            "x": 0,
            "y": -2,
            "z": 0,
            "elements": [
                "minecraft:stone_slab@12"
            ]
        },
        {
            "x": -1,
            "y": -2,
            "z": 0,
            "elements": [
                "minecraft:stone_slab@12"
            ]
        },
        {
            "x": -2,
            "y": 0,
            "z": 1,
            "elements": [
                "minecraft:brick_block@0"
            ]
        }
    ]
}